Workbook

Sheet Hierarchy Level
A1: Hierarchy | B1: Division | C1: Field Force | D1: Designation | F1: DIV
A2: 1 | B2: 01 | C2: L1 | D2: MIO | F2: 01 | G2: Pharma
A3: 2 | B3: 01 | C3: L2 | D3: AM | F3: 02 | G3: AG
A4: 2 | B4: 01 | C4: L3 | D4: SAM | F4: 03 | G4: Onco
A5: 4 | B5: 01 | C5: L4 | D5: RSM | F5: 04 | G5: Optha
A6: 4 | B6: 01 | C6: L5 | D6: ASM | F6: 11 | G6: DNR
A7: 6 | B7: 01 | C7: L6 | D7: DSM
A8: 7 | B8: 01 | C8: L7 | D8: SM
A9: 8 | B9: 01 | C9: L8 | D9: SSM
A10: 9 | B10: 01 | C10: L9 | D10: AGM
A11: 10 | B11: 01 | C11: LA | D11: DGM
A12: 11 | B12: 01 | C12: LB | D12: GM
A13: 12 | B13: 01 | C13: LB | D13: AD
A14: 1 | D14: SMIO
A15: 1 | D15: SIO
A16: 1 | D16: SSIO

Sheet Depot Head - 27 Depots (DNR)
A1: Depot Code | B1: Division | C1: Hierarchy | D1: Depot Head
A2: 1311 | B2: 11 | C2: 8 | D2: EM00013924 | H2: Depot Code | I2: Depot Text
A3: 1312 | B3: 11 | C3: 8 | D3: EM00013924 | H3: 1310 | I3: Paltan Depot
A4: 1314 | B4: 11 | C4: 8 | D4: EM00013924 | H4: 1311 | I4: Dhanmondi Depot
A5: 1329 | B5: 11 | C5: 8 | D5: EM00013924 | H5: 1312 | I5: Uttara Depot
A6: 1334 | B6: 11 | C6: 8 | D6: EM00013924 | H6: 1313 | I6: Narayanganj Depot
A7: 1310 | B7: 11 | C7: 7 | D7: EM00015388 | H7: 1314 | I7: Mymensingh Depot
A8: 1313 | B8: 11 | C8: 7 | D8: EM00015388 | H8: 1315 | I8: Chattogram Depot
A9: 1324 | B9: 11 | C9: 7 | D9: EM00015388 | H9: 1316 | I9: Sylhet Depot
A10: 1325 | B10: 11 | C10: 7 | D10: EM00015388 | H10: 1317 | I10: Cumilla Depot
A11: 1326 | B11: 11 | C11: 7 | D11: EM00015388 | H11: 1318 | I11: Noakhali Depot
A12: 1327 | B12: 11 | C12: 7 | D12: EM00015388 | H12: 1319 | I12: Feni Depot
A13: 1336 | B13: 11 | C13: 7 | D13: EM00015388 | H13: 1320 | I13: Bogura Depot
A14: 1320 | B14: 11 | C14: 7 | D14: EM00015388 | H14: 1321 | I14: Rajshahi Depot
... A28: 1330 | B28: 11 | C28: 8 | D28: EM00013924 | H28: 1335 | I28: Kushtia Depot
H29: 1336 | I29: Keraniganj Depot

Sheet MIO Value Target (DNR)
A1: MIO Code | B1: T. Code | C1: Depot Code | D1: Division | E1: Start Date | F1: End Date | G1: DNR - Target Value (in Lac) | H1: Currency
A2: EM00015585 | B2: DH011-D | C2: 1311 | D2: 11 | E2: 01.09.26 | F2: 30.09.26 | G2: =_xlfn.XLOOKUP(B2,Sheet1!A:A,Sheet1!C:C) -> 321960 | H2: BDT
A3: EM00016041 | B3: DH012-D | C3: 1311 | D3: 11 | E3: 01.09.26 | F3: 30.09.26 | G3: =_xlfn.XLOOKUP(B3,Sheet1!A:A,Sheet1!C:C) -> 380160 | H3: BDT
A4: EM00016381 | B4: DH013-D | C4: 1311 | D4: 11 | E4: 01.09.26 | F4: 30.09.26 | G4: =_xlfn.XLOOKUP(B4,Sheet1!A:A,Sheet1!C:C) -> 337360 | H4: BDT
A5: EM00015619 | B5: DH014-D | C5: 1311 | D5: 11 | E5: 01.09.26 | F5: 30.09.26 | G5: =_xlfn.XLOOKUP(B5,Sheet1!A:A,Sheet1!C:C) -> 493880 | H5: BDT
A6: EM00015733 | B6: DH015-D | C6: 1311 | D6: 11 | E6: 01.09.26 | F6: 30.09.26 | G6: =_xlfn.XLOOKUP(B6,Sheet1!A:A,Sheet1!C:C) -> 450120 | H6: BDT
A7: EM00016421 | B7: DH021-D | C7: 1311 | D7: 11 | E7: 01.09.26 | F7: 30.09.26 | G7: =_xlfn.XLOOKUP(B7,Sheet1!A:A,Sheet1!C:C) -> 398040 | H7: BDT
A8: EM00015587 | B8: DH022-D | C8: 1311 | D8: 11 | E8: 01.09.26 | F8: 30.09.26 | G8: =_xlfn.XLOOKUP(B8,Sheet1!A:A,Sheet1!C:C) -> 409170 | H8: BDT
A9: EM00015607 | B9: DH023-D | C9: 1311 | D9: 11 | E9: 01.09.26 | F9: 30.09.26 | G9: =_xlfn.XLOOKUP(B9,Sheet1!A:A,Sheet1!C:C) -> 359410 | H9: BDT
A10: EM00015608 | B10: DH024-D | C10: 1311 | D10: 11 | E10: 01.09.26 | F10: 30.09.26 | G10: =_xlfn.XLOOKUP(B10,Sheet1!A:A,Sheet1!C:C) -> 336950 | H10: BDT
A11: EM00000000 | B11: DH025-D | C11: 1311 | D11: 11 | E11: 01.09.26 | F11: 30.09.26 | G11: =_xlfn.XLOOKUP(B11,Sheet1!A:A,Sheet1!C:C) -> 318990 | H11: BDT
A12: EM00015621 | B12: DH031-D | C12: 1311 | D12: 11 | E12: 01.09.26 | F12: 30.09.26 | G12: =_xlfn.XLOOKUP(B12,Sheet1!A:A,Sheet1!C:C) -> 564490 | H12: BDT
A13: EM00015606 | B13: DH032-D | C13: 1311 | D13: 11 | E13: 01.09.26 | F13: 30.09.26 | G13: =_xlfn.XLOOKUP(B13,Sheet1!A:A,Sheet1!C:C) -> 623050 | H13: BDT
... A254: EM00015739 | B254: BO015-D | C254: 1320 | D254: 11 | E254: 01.09.26 | F254: 30.09.26 | G254: =_xlfn.XLOOKUP(B254,Sheet1!A:A,Sheet1!C:C) -> 300900 | H254: BDT

Sheet Employee Hierarchy
A1: Employee ID | B1: Depot Code | C1: MIO T. Code | D1: Hierarchy Level | E1: Division | F1: Start Date | G1: End Date | H1: MIO/ SMIO | I1: MIO T. Code | J1: AM/ SAM | K1: AM/ SAM T. Code | L1: SAM | M1: SAM T. Code | N1: RSM | O1: RSM T. Code | P1: ASM | Q1: ASM T. Code | R1: DSM | S1: DSM T. Code | T1: SM | U1: SM T. Code | V1: SSM | W1: SSM T. Code | X1: AGM | Y1: AGM T. Code | Z1: DGM | AA1: DGM T. Code | AB1: GM | AC1: GM T. Code | AD1: AD | AE1: AD T. Code | AH1: Vacant | AI1: CheckID | AJ1: CheckTerr | AK1: Supervisor
A2: EM00015585 | B2: 1311 | C2: DH011-D | D2: 1 | E2: 11 | F2: 46266 | G2: 46295 | H2: EM00015585 | I2: DH011-D | J2: EM00011558 | K2: DH010-D | N2: EM00012371 | O2: RD11001 | P2: EM00000000 | R2: EM00000000 | T2: EM00000000 | V2: EM00013924 | W2: SSM01-D | X2: EM00000000 | Z2: EM00000000 | AB2: EM00000000 | AD2: EM00000000 | AI2: =IF(D2=1,A2=H2,IF(D2=2,A2=J2,IF(D2=4,A2=N2,IF(D2=6,A2=R2,IF(D2=7,A2=T2,IF(D2=8,A2=V2,IF(D2=9,A2=X2,IF(D2=10,A2=Z2,IF(D2=11,A2=AB2,IF(D2=12,A2=AD2,IF(D2=13,A2=AF2))))))))))) -> TRUE | AJ2: =IF(D2=1,C2=I2,IF(D2=2,C2=K2,IF(D2=4,C2=O2,IF(D2=6,C2=S2,IF(D2=7,C2=U2,IF(D2=8,C2=W2,IF(D2=9,C2=Y2,IF(D2=10,C2=AA2,IF(D2=11,C2=AC2,IF(D2=12,C2=AE2,IF(D2=13,C2=AG2))))))))))) -> TRUE | AK2: =IF(D2=1,J2,IF(D2=2,N2,IF(D2=4,R2,IF(D2=6,T2,IF(D2=7,V2,IF(D2=8,X2,IF(D2=9,Z2))))))) -> EM00011558
A3: EM00016041 | B3: 1311 | C3: DH012-D | D3: 1 | E3: 11 | F3: 46266 | G3: 46295 | H3: EM00016041 | I3: DH012-D | J3: EM00011558 | K3: DH010-D | N3: EM00012371 | O3: RD11001 | P3: EM00000000 | R3: EM00000000 | T3: EM00000000 | V3: EM00013924 | W3: SSM01-D | X3: EM00000000 | Z3: EM00000000 | AB3: EM00000000 | AD3: EM00000000 | AI3: =IF(D3=1,A3=H3,IF(D3=2,A3=J3,IF(D3=4,A3=N3,IF(D3=6,A3=R3,IF(D3=7,A3=T3,IF(D3=8,A3=V3,IF(D3=9,A3=X3,IF(D3=10,A3=Z3,IF(D3=11,A3=AB3,IF(D3=12,A3=AD3,IF(D3=13,A3=AF3))))))))))) -> TRUE | AJ3: =IF(D3=1,C3=I3,IF(D3=2,C3=K3,IF(D3=4,C3=O3,IF(D3=6,C3=S3,IF(D3=7,C3=U3,IF(D3=8,C3=W3,IF(D3=9,C3=Y3,IF(D3=10,C3=AA3,IF(D3=11,C3=AC3,IF(D3=12,C3=AE3,IF(D3=13,C3=AG3))))))))))) -> TRUE | AK3: =IF(D3=1,J3,IF(D3=2,N3,IF(D3=4,R3,IF(D3=6,T3,IF(D3=7,V3,IF(D3=8,X3,IF(D3=9,Z3))))))) -> EM00011558
A4: EM00016381 | B4: 1311 | C4: DH013-D | D4: 1 | E4: 11 | F4: 46266 | G4: 46295 | H4: EM00016381 | I4: DH013-D | J4: EM00011558 | K4: DH010-D | N4: EM00012371 | O4: RD11001 | P4: EM00000000 | R4: EM00000000 | T4: EM00000000 | V4: EM00013924 | W4: SSM01-D | X4: EM00000000 | Z4: EM00000000 | AB4: EM00000000 | AD4: EM00000000 | AI4: =IF(D4=1,A4=H4,IF(D4=2,A4=J4,IF(D4=4,A4=N4,IF(D4=6,A4=R4,IF(D4=7,A4=T4,IF(D4=8,A4=V4,IF(D4=9,A4=X4,IF(D4=10,A4=Z4,IF(D4=11,A4=AB4,IF(D4=12,A4=AD4,IF(D4=13,A4=AF4))))))))))) -> TRUE | AJ4: =IF(D4=1,C4=I4,IF(D4=2,C4=K4,IF(D4=4,C4=O4,IF(D4=6,C4=S4,IF(D4=7,C4=U4,IF(D4=8,C4=W4,IF(D4=9,C4=Y4,IF(D4=10,C4=AA4,IF(D4=11,C4=AC4,IF(D4=12,C4=AE4,IF(D4=13,C4=AG4))))))))))) -> TRUE | AK4: =IF(D4=1,J4,IF(D4=2,N4,IF(D4=4,R4,IF(D4=6,T4,IF(D4=7,V4,IF(D4=8,X4,IF(D4=9,Z4))))))) -> EM00011558
A5: EM00015619 | B5: 1311 | C5: DH014-D | D5: 1 | E5: 11 | F5: 46266 | G5: 46295 | H5: EM00015619 | I5: DH014-D | J5: EM00011558 | K5: DH010-D | N5: EM00012371 | O5: RD11001 | P5: EM00000000 | R5: EM00000000 | T5: EM00000000 | V5: EM00013924 | W5: SSM01-D | X5: EM00000000 | Z5: EM00000000 | AB5: EM00000000 | AD5: EM00000000 | AI5: =IF(D5=1,A5=H5,IF(D5=2,A5=J5,IF(D5=4,A5=N5,IF(D5=6,A5=R5,IF(D5=7,A5=T5,IF(D5=8,A5=V5,IF(D5=9,A5=X5,IF(D5=10,A5=Z5,IF(D5=11,A5=AB5,IF(D5=12,A5=AD5,IF(D5=13,A5=AF5))))))))))) -> TRUE | AJ5: =IF(D5=1,C5=I5,IF(D5=2,C5=K5,IF(D5=4,C5=O5,IF(D5=6,C5=S5,IF(D5=7,C5=U5,IF(D5=8,C5=W5,IF(D5=9,C5=Y5,IF(D5=10,C5=AA5,IF(D5=11,C5=AC5,IF(D5=12,C5=AE5,IF(D5=13,C5=AG5))))))))))) -> TRUE | AK5: =IF(D5=1,J5,IF(D5=2,N5,IF(D5=4,R5,IF(D5=6,T5,IF(D5=7,V5,IF(D5=8,X5,IF(D5=9,Z5))))))) -> EM00011558
A6: EM00015733 | B6: 1311 | C6: DH015-D | D6: 1 | E6: 11 | F6: 46266 | G6: 46295 | H6: EM00015733 | I6: DH015-D | J6: EM00011558 | K6: DH010-D | N6: EM00012371 | O6: RD11001 | P6: EM00000000 | R6: EM00000000 | T6: EM00000000 | V6: EM00013924 | W6: SSM01-D | X6: EM00000000 | Z6: EM00000000 | AB6: EM00000000 | AD6: EM00000000 | AI6: =IF(D6=1,A6=H6,IF(D6=2,A6=J6,IF(D6=4,A6=N6,IF(D6=6,A6=R6,IF(D6=7,A6=T6,IF(D6=8,A6=V6,IF(D6=9,A6=X6,IF(D6=10,A6=Z6,IF(D6=11,A6=AB6,IF(D6=12,A6=AD6,IF(D6=13,A6=AF6))))))))))) -> TRUE | AJ6: =IF(D6=1,C6=I6,IF(D6=2,C6=K6,IF(D6=4,C6=O6,IF(D6=6,C6=S6,IF(D6=7,C6=U6,IF(D6=8,C6=W6,IF(D6=9,C6=Y6,IF(D6=10,C6=AA6,IF(D6=11,C6=AC6,IF(D6=12,C6=AE6,IF(D6=13,C6=AG6))))))))))) -> TRUE | AK6: =IF(D6=1,J6,IF(D6=2,N6,IF(D6=4,R6,IF(D6=6,T6,IF(D6=7,V6,IF(D6=8,X6,IF(D6=9,Z6))))))) -> EM00011558
A7: EM00011558 | B7: 1311 | C7: DH010-D | D7: 2 | E7: 11 | F7: 46266 | G7: 46295 | J7: EM00011558 | K7: DH010-D | N7: EM00012371 | O7: RD11001 | P7: EM00000000 | R7: EM00000000 | T7: EM00000000 | V7: EM00013924 | W7: SSM01-D | X7: EM00000000 | Z7: EM00000000 | AB7: EM00000000 | AD7: EM00000000 | AI7: =IF(D7=1,A7=H7,IF(D7=2,A7=J7,IF(D7=4,A7=N7,IF(D7=6,A7=R7,IF(D7=7,A7=T7,IF(D7=8,A7=V7,IF(D7=9,A7=X7,IF(D7=10,A7=Z7,IF(D7=11,A7=AB7,IF(D7=12,A7=AD7,IF(D7=13,A7=AF7))))))))))) -> TRUE | AJ7: =IF(D7=1,C7=I7,IF(D7=2,C7=K7,IF(D7=4,C7=O7,IF(D7=6,C7=S7,IF(D7=7,C7=U7,IF(D7=8,C7=W7,IF(D7=9,C7=Y7,IF(D7=10,C7=AA7,IF(D7=11,C7=AC7,IF(D7=12,C7=AE7,IF(D7=13,C7=AG7))))))))))) -> TRUE | AK7: =IF(D7=1,J7,IF(D7=2,N7,IF(D7=4,R7,IF(D7=6,T7,IF(D7=7,V7,IF(D7=8,X7,IF(D7=9,Z7))))))) -> EM00012371
A8: =_xlfn.XLOOKUP(C8,[1]Sheet2!$D:$D,[1]Sheet2!$C:$C) -> EM00016421 | B8: 1311 | C8: DH021-D | D8: 1 | E8: 11 | F8: 46266 | G8: 46295 | H8: EM00016421 | I8: DH021-D | J8: EM00015656 | K8: DH020-D | N8: EM00012371 | O8: RD11001 | P8: EM00000000 | R8: EM00000000 | T8: EM00000000 | V8: EM00013924 | W8: SSM01-D | X8: EM00000000 | Z8: EM00000000 | AB8: EM00000000 | AD8: EM00000000 | AI8: =IF(D8=1,A8=H8,IF(D8=2,A8=J8,IF(D8=4,A8=N8,IF(D8=6,A8=R8,IF(D8=7,A8=T8,IF(D8=8,A8=V8,IF(D8=9,A8=X8,IF(D8=10,A8=Z8,IF(D8=11,A8=AB8,IF(D8=12,A8=AD8,IF(D8=13,A8=AF8))))))))))) -> TRUE | AJ8: =IF(D8=1,C8=I8,IF(D8=2,C8=K8,IF(D8=4,C8=O8,IF(D8=6,C8=S8,IF(D8=7,C8=U8,IF(D8=8,C8=W8,IF(D8=9,C8=Y8,IF(D8=10,C8=AA8,IF(D8=11,C8=AC8,IF(D8=12,C8=AE8,IF(D8=13,C8=AG8))))))))))) -> TRUE | AK8: =IF(D8=1,J8,IF(D8=2,N8,IF(D8=4,R8,IF(D8=6,T8,IF(D8=7,V8,IF(D8=8,X8,IF(D8=9,Z8))))))) -> EM00015656
A9: =_xlfn.XLOOKUP(C9,[1]Sheet2!$D:$D,[1]Sheet2!$C:$C) -> EM00015587 | B9: 1311 | C9: DH022-D | D9: 1 | E9: 11 | F9: 46266 | G9: 46295 | H9: EM00015587 | I9: DH022-D | J9: EM00015656 | K9: DH020-D | N9: EM00012371 | O9: RD11001 | P9: EM00000000 | R9: EM00000000 | T9: EM00000000 | V9: EM00013924 | W9: SSM01-D | X9: EM00000000 | Z9: EM00000000 | AB9: EM00000000 | AD9: EM00000000 | AI9: =IF(D9=1,A9=H9,IF(D9=2,A9=J9,IF(D9=4,A9=N9,IF(D9=6,A9=R9,IF(D9=7,A9=T9,IF(D9=8,A9=V9,IF(D9=9,A9=X9,IF(D9=10,A9=Z9,IF(D9=11,A9=AB9,IF(D9=12,A9=AD9,IF(D9=13,A9=AF9))))))))))) -> TRUE | AJ9: =IF(D9=1,C9=I9,IF(D9=2,C9=K9,IF(D9=4,C9=O9,IF(D9=6,C9=S9,IF(D9=7,C9=U9,IF(D9=8,C9=W9,IF(D9=9,C9=Y9,IF(D9=10,C9=AA9,IF(D9=11,C9=AC9,IF(D9=12,C9=AE9,IF(D9=13,C9=AG9))))))))))) -> TRUE | AK9: =IF(D9=1,J9,IF(D9=2,N9,IF(D9=4,R9,IF(D9=6,T9,IF(D9=7,V9,IF(D9=8,X9,IF(D9=9,Z9))))))) -> EM00015656
A10: =_xlfn.XLOOKUP(C10,[1]Sheet2!$D:$D,[1]Sheet2!$C:$C) -> EM00015607 | B10: 1311 | C10: DH023-D | D10: 1 | E10: 11 | F10: 46266 | G10: 46295 | H10: EM00015607 | I10: DH023-D | J10: EM00015656 | K10: DH020-D | N10: EM00012371 | O10: RD11001 | P10: EM00000000 | R10: EM00000000 | T10: EM00000000 | V10: EM00013924 | W10: SSM01-D | X10: EM00000000 | Z10: EM00000000 | AB10: EM00000000 | AD10: EM00000000 | AI10: =IF(D10=1,A10=H10,IF(D10=2,A10=J10,IF(D10=4,A10=N10,IF(D10=6,A10=R10,IF(D10=7,A10=T10,IF(D10=8,A10=V10,IF(D10=9,A10=X10,IF(D10=10,A10=Z10,IF(D10=11,A10=AB10,IF(D10=12,A10=AD10,IF(D10=13,A10=AF10))))))))))) -> TRUE | AJ10: =IF(D10=1,C10=I10,IF(D10=2,C10=K10,IF(D10=4,C10=O10,IF(D10=6,C10=S10,IF(D10=7,C10=U10,IF(D10=8,C10=W10,IF(D10=9,C10=Y10,IF(D10=10,C10=AA10,IF(D10=11,C10=AC10,IF(D10=12,C10=AE10,IF(D10=13,C10=AG10))))))))))) -> TRUE | AK10: =IF(D10=1,J10,IF(D10=2,N10,IF(D10=4,R10,IF(D10=6,T10,IF(D10=7,V10,IF(D10=8,X10,IF(D10=9,Z10))))))) -> EM00015656
A11: =_xlfn.XLOOKUP(C11,[1]Sheet2!$D:$D,[1]Sheet2!$C:$C) -> EM00015608 | B11: 1311 | C11: DH024-D | D11: 1 | E11: 11 | F11: 46266 | G11: 46295 | H11: EM00015608 | I11: DH024-D | J11: EM00015656 | K11: DH020-D | N11: EM00012371 | O11: RD11001 | P11: EM00000000 | R11: EM00000000 | T11: EM00000000 | V11: EM00013924 | W11: SSM01-D | X11: EM00000000 | Z11: EM00000000 | AB11: EM00000000 | AD11: EM00000000 | AI11: =IF(D11=1,A11=H11,IF(D11=2,A11=J11,IF(D11=4,A11=N11,IF(D11=6,A11=R11,IF(D11=7,A11=T11,IF(D11=8,A11=V11,IF(D11=9,A11=X11,IF(D11=10,A11=Z11,IF(D11=11,A11=AB11,IF(D11=12,A11=AD11,IF(D11=13,A11=AF11))))))))))) -> TRUE | AJ11: =IF(D11=1,C11=I11,IF(D11=2,C11=K11,IF(D11=4,C11=O11,IF(D11=6,C11=S11,IF(D11=7,C11=U11,IF(D11=8,C11=W11,IF(D11=9,C11=Y11,IF(D11=10,C11=AA11,IF(D11=11,C11=AC11,IF(D11=12,C11=AE11,IF(D11=13,C11=AG11))))))))))) -> TRUE | AK11: =IF(D11=1,J11,IF(D11=2,N11,IF(D11=4,R11,IF(D11=6,T11,IF(D11=7,V11,IF(D11=8,X11,IF(D11=9,Z11))))))) -> EM00015656
A12: =_xlfn.XLOOKUP(C12,[1]Sheet2!$D:$D,[1]Sheet2!$C:$C) -> EM00000000 | B12: 1311 | C12: DH025-D | D12: 1 | E12: 11 | F12: 46266 | G12: 46295 | H12: EM00000000 | I12: DH025-D | J12: EM00015656 | K12: DH020-D | N12: EM00012371 | O12: RD11001 | P12: EM00000000 | R12: EM00000000 | T12: EM00000000 | V12: EM00013924 | W12: SSM01-D | X12: EM00000000 | Z12: EM00000000 | AB12: EM00000000 | AD12: EM00000000 | AI12: =IF(D12=1,A12=H12,IF(D12=2,A12=J12,IF(D12=4,A12=N12,IF(D12=6,A12=R12,IF(D12=7,A12=T12,IF(D12=8,A12=V12,IF(D12=9,A12=X12,IF(D12=10,A12=Z12,IF(D12=11,A12=AB12,IF(D12=12,A12=AD12,IF(D12=13,A12=AF12))))))))))) -> TRUE | AJ12: =IF(D12=1,C12=I12,IF(D12=2,C12=K12,IF(D12=4,C12=O12,IF(D12=6,C12=S12,IF(D12=7,C12=U12,IF(D12=8,C12=W12,IF(D12=9,C12=Y12,IF(D12=10,C12=AA12,IF(D12=11,C12=AC12,IF(D12=12,C12=AE12,IF(D12=13,C12=AG12))))))))))) -> TRUE | AK12: =IF(D12=1,J12,IF(D12=2,N12,IF(D12=4,R12,IF(D12=6,T12,IF(D12=7,V12,IF(D12=8,X12,IF(D12=9,Z12))))))) -> EM00015656
A13: =_xlfn.XLOOKUP(C13,[1]Sheet2!$D:$D,[1]Sheet2!$C:$C) -> EM00015656 | B13: 1311 | C13: DH020-D | D13: 2 | E13: 11 | F13: 46266 | G13: 46295 | J13: EM00015656 | K13: DH020-D | N13: EM00012371 | O13: RD11001 | P13: EM00000000 | R13: EM00000000 | T13: EM00000000 | V13: EM00013924 | W13: SSM01-D | X13: EM00000000 | Z13: EM00000000 | AB13: EM00000000 | AD13: EM00000000 | AI13: =IF(D13=1,A13=H13,IF(D13=2,A13=J13,IF(D13=4,A13=N13,IF(D13=6,A13=R13,IF(D13=7,A13=T13,IF(D13=8,A13=V13,IF(D13=9,A13=X13,IF(D13=10,A13=Z13,IF(D13=11,A13=AB13,IF(D13=12,A13=AD13,IF(D13=13,A13=AF13))))))))))) -> TRUE | AJ13: =IF(D13=1,C13=I13,IF(D13=2,C13=K13,IF(D13=4,C13=O13,IF(D13=6,C13=S13,IF(D13=7,C13=U13,IF(D13=8,C13=W13,IF(D13=9,C13=Y13,IF(D13=10,C13=AA13,IF(D13=11,C13=AC13,IF(D13=12,C13=AE13,IF(D13=13,C13=AG13))))))))))) -> TRUE | AK13: =IF(D13=1,J13,IF(D13=2,N13,IF(D13=4,R13,IF(D13=6,T13,IF(D13=7,V13,IF(D13=8,X13,IF(D13=9,Z13))))))) -> EM00012371
A14: =_xlfn.XLOOKUP(C14,[1]Sheet2!$D:$D,[1]Sheet2!$C:$C) -> EM00015621 | B14: 1311 | C14: DH031-D | D14: 1 | E14: 11 | F14: 46266 | G14: 46295 | H14: EM00015621 | I14: DH031-D | J14: EM00015661 | K14: DH030-D | N14: EM00012371 | O14: RD11001 | P14: EM00000000 | R14: EM00000000 | T14: EM00000000 | V14: EM00013924 | W14: SSM01-D | X14: EM00000000 | Z14: EM00000000 | AB14: EM00000000 | AD14: EM00000000 | AI14: =IF(D14=1,A14=H14,IF(D14=2,A14=J14,IF(D14=4,A14=N14,IF(D14=6,A14=R14,IF(D14=7,A14=T14,IF(D14=8,A14=V14,IF(D14=9,A14=X14,IF(D14=10,A14=Z14,IF(D14=11,A14=AB14,IF(D14=12,A14=AD14,IF(D14=13,A14=AF14))))))))))) -> TRUE | AJ14: =IF(D14=1,C14=I14,IF(D14=2,C14=K14,IF(D14=4,C14=O14,IF(D14=6,C14=S14,IF(D14=7,C14=U14,IF(D14=8,C14=W14,IF(D14=9,C14=Y14,IF(D14=10,C14=AA14,IF(D14=11,C14=AC14,IF(D14=12,C14=AE14,IF(D14=13,C14=AG14))))))))))) -> TRUE | AK14: =IF(D14=1,J14,IF(D14=2,N14,IF(D14=4,R14,IF(D14=6,T14,IF(D14=7,V14,IF(D14=8,X14,IF(D14=9,Z14))))))) -> EM00015661
A15: =_xlfn.XLOOKUP(C15,[1]Sheet2!$D:$D,[1]Sheet2!$C:$C) -> EM00015606 | B15: 1311 | C15: DH032-D | D15: 1 | E15: 11 | F15: 46266 | G15: 46295 | H15: EM00015606 | I15: DH032-D | J15: EM00015661 | K15: DH030-D | N15: EM00012371 | O15: RD11001 | P15: EM00000000 | R15: EM00000000 | T15: EM00000000 | V15: EM00013924 | W15: SSM01-D | X15: EM00000000 | Z15: EM00000000 | AB15: EM00000000 | AD15: EM00000000 | AI15: =IF(D15=1,A15=H15,IF(D15=2,A15=J15,IF(D15=4,A15=N15,IF(D15=6,A15=R15,IF(D15=7,A15=T15,IF(D15=8,A15=V15,IF(D15=9,A15=X15,IF(D15=10,A15=Z15,IF(D15=11,A15=AB15,IF(D15=12,A15=AD15,IF(D15=13,A15=AF15))))))))))) -> TRUE | AJ15: =IF(D15=1,C15=I15,IF(D15=2,C15=K15,IF(D15=4,C15=O15,IF(D15=6,C15=S15,IF(D15=7,C15=U15,IF(D15=8,C15=W15,IF(D15=9,C15=Y15,IF(D15=10,C15=AA15,IF(D15=11,C15=AC15,IF(D15=12,C15=AE15,IF(D15=13,C15=AG15))))))))))) -> TRUE | AK15: =IF(D15=1,J15,IF(D15=2,N15,IF(D15=4,R15,IF(D15=6,T15,IF(D15=7,V15,IF(D15=8,X15,IF(D15=9,Z15))))))) -> EM00015661
A16: =_xlfn.XLOOKUP(C16,[1]Sheet2!$D:$D,[1]Sheet2!$C:$C) -> EM00016045 | B16: 1311 | C16: DH033-D | D16: 1 | E16: 11 | F16: 46266 | G16: 46295 | H16: EM00016045 | I16: DH033-D | J16: EM00015661 | K16: DH030-D | N16: EM00012371 | O16: RD11001 | P16: EM00000000 | R16: EM00000000 | T16: EM00000000 | V16: EM00013924 | W16: SSM01-D | X16: EM00000000 | Z16: EM00000000 | AB16: EM00000000 | AD16: EM00000000 | AI16: =IF(D16=1,A16=H16,IF(D16=2,A16=J16,IF(D16=4,A16=N16,IF(D16=6,A16=R16,IF(D16=7,A16=T16,IF(D16=8,A16=V16,IF(D16=9,A16=X16,IF(D16=10,A16=Z16,IF(D16=11,A16=AB16,IF(D16=12,A16=AD16,IF(D16=13,A16=AF16))))))))))) -> TRUE | AJ16: =IF(D16=1,C16=I16,IF(D16=2,C16=K16,IF(D16=4,C16=O16,IF(D16=6,C16=S16,IF(D16=7,C16=U16,IF(D16=8,C16=W16,IF(D16=9,C16=Y16,IF(D16=10,C16=AA16,IF(D16=11,C16=AC16,IF(D16=12,C16=AE16,IF(D16=13,C16=AG16))))))))))) -> TRUE | AK16: =IF(D16=1,J16,IF(D16=2,N16,IF(D16=4,R16,IF(D16=6,T16,IF(D16=7,V16,IF(D16=8,X16,IF(D16=9,Z16))))))) -> EM00015661
A17: =_xlfn.XLOOKUP(C17,[1]Sheet2!$D:$D,[1]Sheet2!$C:$C) -> EM00000000 | B17: 1311 | C17: DH034-D | D17: 1 | E17: 11 | F17: 46266 | G17: 46295 | H17: EM00000000 | I17: DH034-D | J17: EM00015661 | K17: DH030-D | N17: EM00012371 | O17: RD11001 | P17: EM00000000 | R17: EM00000000 | T17: EM00000000 | V17: EM00013924 | W17: SSM01-D | X17: EM00000000 | Z17: EM00000000 | AB17: EM00000000 | AD17: EM00000000 | AI17: =IF(D17=1,A17=H17,IF(D17=2,A17=J17,IF(D17=4,A17=N17,IF(D17=6,A17=R17,IF(D17=7,A17=T17,IF(D17=8,A17=V17,IF(D17=9,A17=X17,IF(D17=10,A17=Z17,IF(D17=11,A17=AB17,IF(D17=12,A17=AD17,IF(D17=13,A17=AF17))))))))))) -> TRUE | AJ17: =IF(D17=1,C17=I17,IF(D17=2,C17=K17,IF(D17=4,C17=O17,IF(D17=6,C17=S17,IF(D17=7,C17=U17,IF(D17=8,C17=W17,IF(D17=9,C17=Y17,IF(D17=10,C17=AA17,IF(D17=11,C17=AC17,IF(D17=12,C17=AE17,IF(D17=13,C17=AG17))))))))))) -> TRUE | AK17: =IF(D17=1,J17,IF(D17=2,N17,IF(D17=4,R17,IF(D17=6,T17,IF(D17=7,V17,IF(D17=8,X17,IF(D17=9,Z17))))))) -> EM00015661
A18: =_xlfn.XLOOKUP(C18,[1]Sheet2!$D:$D,[1]Sheet2!$C:$C) -> EM00000000 | B18: 1311 | C18: DH035-D | D18: 1 | E18: 11 | F18: 46266 | G18: 46295 | H18: EM00000000 | I18: DH035-D | J18: EM00015661 | K18: DH030-D | N18: EM00012371 | O18: RD11001 | P18: EM00000000 | R18: EM00000000 | T18: EM00000000 | V18: EM00013924 | W18: SSM01-D | X18: EM00000000 | Z18: EM00000000 | AB18: EM00000000 | AD18: EM00000000 | AI18: =IF(D18=1,A18=H18,IF(D18=2,A18=J18,IF(D18=4,A18=N18,IF(D18=6,A18=R18,IF(D18=7,A18=T18,IF(D18=8,A18=V18,IF(D18=9,A18=X18,IF(D18=10,A18=Z18,IF(D18=11,A18=AB18,IF(D18=12,A18=AD18,IF(D18=13,A18=AF18))))))))))) -> TRUE | AJ18: =IF(D18=1,C18=I18,IF(D18=2,C18=K18,IF(D18=4,C18=O18,IF(D18=6,C18=S18,IF(D18=7,C18=U18,IF(D18=8,C18=W18,IF(D18=9,C18=Y18,IF(D18=10,C18=AA18,IF(D18=11,C18=AC18,IF(D18=12,C18=AE18,IF(D18=13,C18=AG18))))))))))) -> TRUE | AK18: =IF(D18=1,J18,IF(D18=2,N18,IF(D18=4,R18,IF(D18=6,T18,IF(D18=7,V18,IF(D18=8,X18,IF(D18=9,Z18))))))) -> EM00015661
A19: =_xlfn.XLOOKUP(C19,[1]Sheet2!$D:$D,[1]Sheet2!$C:$C) -> EM00015661 | B19: 1311 | C19: DH030-D | D19: 2 | E19: 11 | F19: 46266 | G19: 46295 | J19: EM00015661 | K19: DH030-D | N19: EM00012371 | O19: RD11001 | P19: EM00000000 | R19: EM00000000 | T19: EM00000000 | V19: EM00013924 | W19: SSM01-D | X19: EM00000000 | Z19: EM00000000 | AB19: EM00000000 | AD19: EM00000000 | AI19: =IF(D19=1,A19=H19,IF(D19=2,A19=J19,IF(D19=4,A19=N19,IF(D19=6,A19=R19,IF(D19=7,A19=T19,IF(D19=8,A19=V19,IF(D19=9,A19=X19,IF(D19=10,A19=Z19,IF(D19=11,A19=AB19,IF(D19=12,A19=AD19,IF(D19=13,A19=AF19))))))))))) -> TRUE | AJ19: =IF(D19=1,C19=I19,IF(D19=2,C19=K19,IF(D19=4,C19=O19,IF(D19=6,C19=S19,IF(D19=7,C19=U19,IF(D19=8,C19=W19,IF(D19=9,C19=Y19,IF(D19=10,C19=AA19,IF(D19=11,C19=AC19,IF(D19=12,C19=AE19,IF(D19=13,C19=AG19))))))))))) -> TRUE | AK19: =IF(D19=1,J19,IF(D19=2,N19,IF(D19=4,R19,IF(D19=6,T19,IF(D19=7,V19,IF(D19=8,X19,IF(D19=9,Z19))))))) -> EM00012371
A20: =_xlfn.XLOOKUP(C20,[1]Sheet2!$D:$D,[1]Sheet2!$C:$C) -> EM00015983 | B20: 1310 | C20: PA011-D | D20: 1 | E20: 11 | F20: 46266 | G20: 46295 | H20: EM00015983 | I20: PA011-D | J20: EM00007671 | K20: PA010-D | N20: EM00012371 | O20: RD11001 | P20: EM00000000 | R20: EM00000000 | T20: EM00000000 | V20: EM00013924 | W20: SSM01-D | X20: EM00000000 | Z20: EM00000000 | AB20: EM00000000 | AD20: EM00000000 | AI20: =IF(D20=1,A20=H20,IF(D20=2,A20=J20,IF(D20=4,A20=N20,IF(D20=6,A20=R20,IF(D20=7,A20=T20,IF(D20=8,A20=V20,IF(D20=9,A20=X20,IF(D20=10,A20=Z20,IF(D20=11,A20=AB20,IF(D20=12,A20=AD20,IF(D20=13,A20=AF20))))))))))) -> TRUE | AJ20: =IF(D20=1,C20=I20,IF(D20=2,C20=K20,IF(D20=4,C20=O20,IF(D20=6,C20=S20,IF(D20=7,C20=U20,IF(D20=8,C20=W20,IF(D20=9,C20=Y20,IF(D20=10,C20=AA20,IF(D20=11,C20=AC20,IF(D20=12,C20=AE20,IF(D20=13,C20=AG20))))))))))) -> TRUE | AK20: =IF(D20=1,J20,IF(D20=2,N20,IF(D20=4,R20,IF(D20=6,T20,IF(D20=7,V20,IF(D20=8,X20,IF(D20=9,Z20))))))) -> EM00007671
A21: =_xlfn.XLOOKUP(C21,[1]Sheet2!$D:$D,[1]Sheet2!$C:$C) -> EM00015722 | B21: 1310 | C21: PA012-D | D21: 1 | E21: 11 | F21: 46266 | G21: 46295 | H21: EM00015722 | I21: PA012-D | J21: EM00007671 | K21: PA010-D | N21: EM00012371 | O21: RD11001 | P21: EM00000000 | R21: EM00000000 | T21: EM00000000 | V21: EM00013924 | W21: SSM01-D | X21: EM00000000 | Z21: EM00000000 | AB21: EM00000000 | AD21: EM00000000 | AI21: =IF(D21=1,A21=H21,IF(D21=2,A21=J21,IF(D21=4,A21=N21,IF(D21=6,A21=R21,IF(D21=7,A21=T21,IF(D21=8,A21=V21,IF(D21=9,A21=X21,IF(D21=10,A21=Z21,IF(D21=11,A21=AB21,IF(D21=12,A21=AD21,IF(D21=13,A21=AF21))))))))))) -> TRUE | AJ21: =IF(D21=1,C21=I21,IF(D21=2,C21=K21,IF(D21=4,C21=O21,IF(D21=6,C21=S21,IF(D21=7,C21=U21,IF(D21=8,C21=W21,IF(D21=9,C21=Y21,IF(D21=10,C21=AA21,IF(D21=11,C21=AC21,IF(D21=12,C21=AE21,IF(D21=13,C21=AG21))))))))))) -> TRUE | AK21: =IF(D21=1,J21,IF(D21=2,N21,IF(D21=4,R21,IF(D21=6,T21,IF(D21=7,V21,IF(D21=8,X21,IF(D21=9,Z21))))))) -> EM00007671
A22: =_xlfn.XLOOKUP(C22,[1]Sheet2!$D:$D,[1]Sheet2!$C:$C) -> EM00016052 | B22: 1310 | C22: PA013-D | D22: 1 | E22: 11 | F22: 46266 | G22: 46295 | H22: EM00016052 | I22: PA013-D | J22: EM00007671 | K22: PA010-D | N22: EM00012371 | O22: RD11001 | P22: EM00000000 | R22: EM00000000 | T22: EM00000000 | V22: EM00013924 | W22: SSM01-D | X22: EM00000000 | Z22: EM00000000 | AB22: EM00000000 | AD22: EM00000000 | AI22: =IF(D22=1,A22=H22,IF(D22=2,A22=J22,IF(D22=4,A22=N22,IF(D22=6,A22=R22,IF(D22=7,A22=T22,IF(D22=8,A22=V22,IF(D22=9,A22=X22,IF(D22=10,A22=Z22,IF(D22=11,A22=AB22,IF(D22=12,A22=AD22,IF(D22=13,A22=AF22))))))))))) -> TRUE | AJ22: =IF(D22=1,C22=I22,IF(D22=2,C22=K22,IF(D22=4,C22=O22,IF(D22=6,C22=S22,IF(D22=7,C22=U22,IF(D22=8,C22=W22,IF(D22=9,C22=Y22,IF(D22=10,C22=AA22,IF(D22=11,C22=AC22,IF(D22=12,C22=AE22,IF(D22=13,C22=AG22))))))))))) -> TRUE | AK22: =IF(D22=1,J22,IF(D22=2,N22,IF(D22=4,R22,IF(D22=6,T22,IF(D22=7,V22,IF(D22=8,X22,IF(D22=9,Z22))))))) -> EM00007671
A23: =_xlfn.XLOOKUP(C23,[1]Sheet2!$D:$D,[1]Sheet2!$C:$C) -> EM00015723 | B23: 1310 | C23: PA014-D | D23: 1 | E23: 11 | F23: 46266 | G23: 46295 | H23: EM00015723 | I23: PA014-D | J23: EM00007671 | K23: PA010-D | N23: EM00012371 | O23: RD11001 | P23: EM00000000 | R23: EM00000000 | T23: EM00000000 | V23: EM00013924 | W23: SSM01-D | X23: EM00000000 | Z23: EM00000000 | AB23: EM00000000 | AD23: EM00000000 | AI23: =IF(D23=1,A23=H23,IF(D23=2,A23=J23,IF(D23=4,A23=N23,IF(D23=6,A23=R23,IF(D23=7,A23=T23,IF(D23=8,A23=V23,IF(D23=9,A23=X23,IF(D23=10,A23=Z23,IF(D23=11,A23=AB23,IF(D23=12,A23=AD23,IF(D23=13,A23=AF23))))))))))) -> TRUE | AJ23: =IF(D23=1,C23=I23,IF(D23=2,C23=K23,IF(D23=4,C23=O23,IF(D23=6,C23=S23,IF(D23=7,C23=U23,IF(D23=8,C23=W23,IF(D23=9,C23=Y23,IF(D23=10,C23=AA23,IF(D23=11,C23=AC23,IF(D23=12,C23=AE23,IF(D23=13,C23=AG23))))))))))) -> TRUE | AK23: =IF(D23=1,J23,IF(D23=2,N23,IF(D23=4,R23,IF(D23=6,T23,IF(D23=7,V23,IF(D23=8,X23,IF(D23=9,Z23))))))) -> EM00007671
A24: =_xlfn.XLOOKUP(C24,[1]Sheet2!$D:$D,[1]Sheet2!$C:$C) -> EM00015582 | B24: 1310 | C24: PA015-D | D24: 1 | E24: 11 | F24: 46266 | G24: 46295 | H24: EM00015582 | I24: PA015-D | J24: EM00007671 | K24: PA010-D | N24: EM00012371 | O24: RD11001 | P24: EM00000000 | R24: EM00000000 | T24: EM00000000 | V24: EM00013924 | W24: SSM01-D | X24: EM00000000 | Z24: EM00000000 | AB24: EM00000000 | AD24: EM00000000 | AI24: =IF(D24=1,A24=H24,IF(D24=2,A24=J24,IF(D24=4,A24=N24,IF(D24=6,A24=R24,IF(D24=7,A24=T24,IF(D24=8,A24=V24,IF(D24=9,A24=X24,IF(D24=10,A24=Z24,IF(D24=11,A24=AB24,IF(D24=12,A24=AD24,IF(D24=13,A24=AF24))))))))))) -> TRUE | AJ24: =IF(D24=1,C24=I24,IF(D24=2,C24=K24,IF(D24=4,C24=O24,IF(D24=6,C24=S24,IF(D24=7,C24=U24,IF(D24=8,C24=W24,IF(D24=9,C24=Y24,IF(D24=10,C24=AA24,IF(D24=11,C24=AC24,IF(D24=12,C24=AE24,IF(D24=13,C24=AG24))))))))))) -> TRUE | AK24: =IF(D24=1,J24,IF(D24=2,N24,IF(D24=4,R24,IF(D24=6,T24,IF(D24=7,V24,IF(D24=8,X24,IF(D24=9,Z24))))))) -> EM00007671
A25: =_xlfn.XLOOKUP(C25,[1]Sheet2!$D:$D,[1]Sheet2!$C:$C) -> EM00016053 | B25: 1310 | C25: PA016-D | D25: 1 | E25: 11 | F25: 46266 | G25: 46295 | H25: EM00016053 | I25: PA016-D | J25: EM00007671 | K25: PA010-D | N25: EM00012371 | O25: RD11001 | P25: EM00000000 | R25: EM00000000 | T25: EM00000000 | V25: EM00013924 | W25: SSM01-D | X25: EM00000000 | Z25: EM00000000 | AB25: EM00000000 | AD25: EM00000000 | AI25: =IF(D25=1,A25=H25,IF(D25=2,A25=J25,IF(D25=4,A25=N25,IF(D25=6,A25=R25,IF(D25=7,A25=T25,IF(D25=8,A25=V25,IF(D25=9,A25=X25,IF(D25=10,A25=Z25,IF(D25=11,A25=AB25,IF(D25=12,A25=AD25,IF(D25=13,A25=AF25))))))))))) -> TRUE | AJ25: =IF(D25=1,C25=I25,IF(D25=2,C25=K25,IF(D25=4,C25=O25,IF(D25=6,C25=S25,IF(D25=7,C25=U25,IF(D25=8,C25=W25,IF(D25=9,C25=Y25,IF(D25=10,C25=AA25,IF(D25=11,C25=AC25,IF(D25=12,C25=AE25,IF(D25=13,C25=AG25))))))))))) -> TRUE | AK25: =IF(D25=1,J25,IF(D25=2,N25,IF(D25=4,R25,IF(D25=6,T25,IF(D25=7,V25,IF(D25=8,X25,IF(D25=9,Z25))))))) -> EM00007671
A26: =_xlfn.XLOOKUP(C26,[1]Sheet2!$D:$D,[1]Sheet2!$C:$C) -> EM00007671 | B26: 1310 | C26: PA010-D | D26: 2 | E26: 11 | F26: 46266 | G26: 46295 | J26: EM00007671 | K26: PA010-D | N26: EM00012371 | O26: RD11001 | P26: EM00000000 | R26: EM00000000 | T26: EM00000000 | V26: EM00013924 | W26: SSM01-D | X26: EM00000000 | Z26: EM00000000 | AB26: EM00000000 | AD26: EM00000000 | AI26: =IF(D26=1,A26=H26,IF(D26=2,A26=J26,IF(D26=4,A26=N26,IF(D26=6,A26=R26,IF(D26=7,A26=T26,IF(D26=8,A26=V26,IF(D26=9,A26=X26,IF(D26=10,A26=Z26,IF(D26=11,A26=AB26,IF(D26=12,A26=AD26,IF(D26=13,A26=AF26))))))))))) -> TRUE | AJ26: =IF(D26=1,C26=I26,IF(D26=2,C26=K26,IF(D26=4,C26=O26,IF(D26=6,C26=S26,IF(D26=7,C26=U26,IF(D26=8,C26=W26,IF(D26=9,C26=Y26,IF(D26=10,C26=AA26,IF(D26=11,C26=AC26,IF(D26=12,C26=AE26,IF(D26=13,C26=AG26))))))))))) -> TRUE | AK26: =IF(D26=1,J26,IF(D26=2,N26,IF(D26=4,R26,IF(D26=6,T26,IF(D26=7,V26,IF(D26=8,X26,IF(D26=9,Z26))))))) -> EM00012371
A27: =_xlfn.XLOOKUP(C27,[1]Sheet2!$D:$D,[1]Sheet2!$C:$C) -> EM00015734 | B27: 1311 | C27: DH041-D | D27: 1 | E27: 11 | F27: 46266 | G27: 46295 | H27: EM00015734 | I27: DH041-D | J27: EM00000000 | K27: DH040-D | N27: EM00012371 | O27: RD11001 | P27: EM00000000 | R27: EM00000000 | T27: EM00000000 | V27: EM00013924 | W27: SSM01-D | X27: EM00000000 | Z27: EM00000000 | AB27: EM00000000 | AD27: EM00000000 | AI27: =IF(D27=1,A27=H27,IF(D27=2,A27=J27,IF(D27=4,A27=N27,IF(D27=6,A27=R27,IF(D27=7,A27=T27,IF(D27=8,A27=V27,IF(D27=9,A27=X27,IF(D27=10,A27=Z27,IF(D27=11,A27=AB27,IF(D27=12,A27=AD27,IF(D27=13,A27=AF27))))))))))) -> TRUE | AJ27: =IF(D27=1,C27=I27,IF(D27=2,C27=K27,IF(D27=4,C27=O27,IF(D27=6,C27=S27,IF(D27=7,C27=U27,IF(D27=8,C27=W27,IF(D27=9,C27=Y27,IF(D27=10,C27=AA27,IF(D27=11,C27=AC27,IF(D27=12,C27=AE27,IF(D27=13,C27=AG27))))))))))) -> TRUE | AK27: =IF(D27=1,J27,IF(D27=2,N27,IF(D27=4,R27,IF(D27=6,T27,IF(D27=7,V27,IF(D27=8,X27,IF(D27=9,Z27))))))) -> EM00000000
A28: =_xlfn.XLOOKUP(C28,[1]Sheet2!$D:$D,[1]Sheet2!$C:$C) -> EM00015992 | B28: 1311 | C28: DH042-D | D28: 1 | E28: 11 | F28: 46266 | G28: 46295 | H28: EM00015992 | I28: DH042-D | J28: EM00000000 | K28: DH040-D | N28: EM00012371 | O28: RD11001 | P28: EM00000000 | R28: EM00000000 | T28: EM00000000 | V28: EM00013924 | W28: SSM01-D | X28: EM00000000 | Z28: EM00000000 | AB28: EM00000000 | AD28: EM00000000 | AI28: =IF(D28=1,A28=H28,IF(D28=2,A28=J28,IF(D28=4,A28=N28,IF(D28=6,A28=R28,IF(D28=7,A28=T28,IF(D28=8,A28=V28,IF(D28=9,A28=X28,IF(D28=10,A28=Z28,IF(D28=11,A28=AB28,IF(D28=12,A28=AD28,IF(D28=13,A28=AF28))))))))))) -> TRUE | AJ28: =IF(D28=1,C28=I28,IF(D28=2,C28=K28,IF(D28=4,C28=O28,IF(D28=6,C28=S28,IF(D28=7,C28=U28,IF(D28=8,C28=W28,IF(D28=9,C28=Y28,IF(D28=10,C28=AA28,IF(D28=11,C28=AC28,IF(D28=12,C28=AE28,IF(D28=13,C28=AG28))))))))))) -> TRUE | AK28: =IF(D28=1,J28,IF(D28=2,N28,IF(D28=4,R28,IF(D28=6,T28,IF(D28=7,V28,IF(D28=8,X28,IF(D28=9,Z28))))))) -> EM00000000
A29: =_xlfn.XLOOKUP(C29,[1]Sheet2!$D:$D,[1]Sheet2!$C:$C) -> EM00015586 | B29: 1311 | C29: DH043-D | D29: 1 | E29: 11 | F29: 46266 | G29: 46295 | H29: EM00015586 | I29: DH043-D | J29: EM00000000 | K29: DH040-D | N29: EM00012371 | O29: RD11001 | P29: EM00000000 | R29: EM00000000 | T29: EM00000000 | V29: EM00013924 | W29: SSM01-D | X29: EM00000000 | Z29: EM00000000 | AB29: EM00000000 | AD29: EM00000000 | AI29: =IF(D29=1,A29=H29,IF(D29=2,A29=J29,IF(D29=4,A29=N29,IF(D29=6,A29=R29,IF(D29=7,A29=T29,IF(D29=8,A29=V29,IF(D29=9,A29=X29,IF(D29=10,A29=Z29,IF(D29=11,A29=AB29,IF(D29=12,A29=AD29,IF(D29=13,A29=AF29))))))))))) -> TRUE | AJ29: =IF(D29=1,C29=I29,IF(D29=2,C29=K29,IF(D29=4,C29=O29,IF(D29=6,C29=S29,IF(D29=7,C29=U29,IF(D29=8,C29=W29,IF(D29=9,C29=Y29,IF(D29=10,C29=AA29,IF(D29=11,C29=AC29,IF(D29=12,C29=AE29,IF(D29=13,C29=AG29))))))))))) -> TRUE | AK29: =IF(D29=1,J29,IF(D29=2,N29,IF(D29=4,R29,IF(D29=6,T29,IF(D29=7,V29,IF(D29=8,X29,IF(D29=9,Z29))))))) -> EM00000000
A30: =_xlfn.XLOOKUP(C30,[1]Sheet2!$D:$D,[1]Sheet2!$C:$C) -> EM00015736 | B30: 1311 | C30: DH044-D | D30: 1 | E30: 11 | F30: 46266 | G30: 46295 | H30: EM00015736 | I30: DH044-D | J30: EM00000000 | K30: DH040-D | N30: EM00012371 | O30: RD11001 | P30: EM00000000 | R30: EM00000000 | T30: EM00000000 | V30: EM00013924 | W30: SSM01-D | X30: EM00000000 | Z30: EM00000000 | AB30: EM00000000 | AD30: EM00000000 | AI30: =IF(D30=1,A30=H30,IF(D30=2,A30=J30,IF(D30=4,A30=N30,IF(D30=6,A30=R30,IF(D30=7,A30=T30,IF(D30=8,A30=V30,IF(D30=9,A30=X30,IF(D30=10,A30=Z30,IF(D30=11,A30=AB30,IF(D30=12,A30=AD30,IF(D30=13,A30=AF30))))))))))) -> TRUE | AJ30: =IF(D30=1,C30=I30,IF(D30=2,C30=K30,IF(D30=4,C30=O30,IF(D30=6,C30=S30,IF(D30=7,C30=U30,IF(D30=8,C30=W30,IF(D30=9,C30=Y30,IF(D30=10,C30=AA30,IF(D30=11,C30=AC30,IF(D30=12,C30=AE30,IF(D30=13,C30=AG30))))))))))) -> TRUE | AK30: =IF(D30=1,J30,IF(D30=2,N30,IF(D30=4,R30,IF(D30=6,T30,IF(D30=7,V30,IF(D30=8,X30,IF(D30=9,Z30))))))) -> EM00000000
A31: =_xlfn.XLOOKUP(C31,[1]Sheet2!$D:$D,[1]Sheet2!$C:$C) -> EM00000000 | B31: 1311 | C31: DH040-D | D31: 2 | E31: 11 | F31: 46266 | G31: 46295 | J31: EM00000000 | K31: DH040-D | N31: EM00012371 | O31: RD11001 | P31: EM00000000 | R31: EM00000000 | T31: EM00000000 | V31: EM00013924 | W31: SSM01-D | X31: EM00000000 | Z31: EM00000000 | AB31: EM00000000 | AD31: EM00000000 | AI31: =IF(D31=1,A31=H31,IF(D31=2,A31=J31,IF(D31=4,A31=N31,IF(D31=6,A31=R31,IF(D31=7,A31=T31,IF(D31=8,A31=V31,IF(D31=9,A31=X31,IF(D31=10,A31=Z31,IF(D31=11,A31=AB31,IF(D31=12,A31=AD31,IF(D31=13,A31=AF31))))))))))) -> TRUE | AJ31: =IF(D31=1,C31=I31,IF(D31=2,C31=K31,IF(D31=4,C31=O31,IF(D31=6,C31=S31,IF(D31=7,C31=U31,IF(D31=8,C31=W31,IF(D31=9,C31=Y31,IF(D31=10,C31=AA31,IF(D31=11,C31=AC31,IF(D31=12,C31=AE31,IF(D31=13,C31=AG31))))))))))) -> TRUE | AK31: =IF(D31=1,J31,IF(D31=2,N31,IF(D31=4,R31,IF(D31=6,T31,IF(D31=7,V31,IF(D31=8,X31,IF(D31=9,Z31))))))) -> EM00012371
A32: EM00012371 | B32: 1311 | C32: RD11001 | D32: 4 | E32: 11 | F32: 46266 | G32: 46295 | N32: EM00012371 | O32: RD11001 | P32: EM00000000 | R32: EM00000000 | T32: EM00000000 | V32: EM00013924 | W32: SSM01-D | X32: EM00000000 | Z32: EM00000000 | AB32: EM00000000 | AD32: EM00000000 | AI32: =IF(D32=1,A32=H32,IF(D32=2,A32=J32,IF(D32=4,A32=N32,IF(D32=6,A32=R32,IF(D32=7,A32=T32,IF(D32=8,A32=V32,IF(D32=9,A32=X32,IF(D32=10,A32=Z32,IF(D32=11,A32=AB32,IF(D32=12,A32=AD32,IF(D32=13,A32=AF32))))))))))) -> TRUE | AJ32: =IF(D32=1,C32=I32,IF(D32=2,C32=K32,IF(D32=4,C32=O32,IF(D32=6,C32=S32,IF(D32=7,C32=U32,IF(D32=8,C32=W32,IF(D32=9,C32=Y32,IF(D32=10,C32=AA32,IF(D32=11,C32=AC32,IF(D32=12,C32=AE32,IF(D32=13,C32=AG32))))))))))) -> TRUE | AK32: =IF(D32=1,J32,IF(D32=2,N32,IF(D32=4,R32,IF(D32=6,T32,IF(D32=7,V32,IF(D32=8,X32,IF(D32=9,Z32))))))) -> EM00000000
A33: EM00012371 | B33: 1310 | C33: RD11001 | D33: 4 | E33: 11 | F33: 46266 | G33: 46295 | N33: EM00012371 | O33: RD11001 | P33: EM00000000 | R33: EM00000000 | T33: EM00000000 | V33: EM00013924 | W33: SSM01-D | X33: EM00000000 | Z33: EM00000000 | AB33: EM00000000 | AD33: EM00000000 | AI33: =IF(D33=1,A33=H33,IF(D33=2,A33=J33,IF(D33=4,A33=N33,IF(D33=6,A33=R33,IF(D33=7,A33=T33,IF(D33=8,A33=V33,IF(D33=9,A33=X33,IF(D33=10,A33=Z33,IF(D33=11,A33=AB33,IF(D33=12,A33=AD33,IF(D33=13,A33=AF33))))))))))) -> TRUE | AJ33: =IF(D33=1,C33=I33,IF(D33=2,C33=K33,IF(D33=4,C33=O33,IF(D33=6,C33=S33,IF(D33=7,C33=U33,IF(D33=8,C33=W33,IF(D33=9,C33=Y33,IF(D33=10,C33=AA33,IF(D33=11,C33=AC33,IF(D33=12,C33=AE33,IF(D33=13,C33=AG33))))))))))) -> TRUE | AK33: =IF(D33=1,J33,IF(D33=2,N33,IF(D33=4,R33,IF(D33=6,T33,IF(D33=7,V33,IF(D33=8,X33,IF(D33=9,Z33))))))) -> EM00000000
A34: =_xlfn.XLOOKUP(C34,[1]Sheet2!$D:$D,[1]Sheet2!$C:$C) -> EM00015760 | B34: 1334 | C34: KI011-D | D34: 1 | E34: 11 | F34: 46266 | G34: 46295 | H34: EM00015760 | I34: KI011-D | J34: EM00000000 | K34: KI010-D | N34: EM00015556 | O34: RD11003 | P34: EM00000000 | R34: EM00000000 | T34: EM00000000 | V34: EM00013924 | W34: SSM01-D | X34: EM00000000 | Z34: EM00000000 | AB34: EM00000000 | AD34: EM00000000 | AI34: =IF(D34=1,A34=H34,IF(D34=2,A34=J34,IF(D34=4,A34=N34,IF(D34=6,A34=R34,IF(D34=7,A34=T34,IF(D34=8,A34=V34,IF(D34=9,A34=X34,IF(D34=10,A34=Z34,IF(D34=11,A34=AB34,IF(D34=12,A34=AD34,IF(D34=13,A34=AF34))))))))))) -> TRUE | AJ34: =IF(D34=1,C34=I34,IF(D34=2,C34=K34,IF(D34=4,C34=O34,IF(D34=6,C34=S34,IF(D34=7,C34=U34,IF(D34=8,C34=W34,IF(D34=9,C34=Y34,IF(D34=10,C34=AA34,IF(D34=11,C34=AC34,IF(D34=12,C34=AE34,IF(D34=13,C34=AG34))))))))))) -> TRUE | AK34: =IF(D34=1,J34,IF(D34=2,N34,IF(D34=4,R34,IF(D34=6,T34,IF(D34=7,V34,IF(D34=8,X34,IF(D34=9,Z34))))))) -> EM00000000
A35: =_xlfn.XLOOKUP(C35,[1]Sheet2!$D:$D,[1]Sheet2!$C:$C) -> EM00015759 | B35: 1334 | C35: KI012-D | D35: 1 | E35: 11 | F35: 46266 | G35: 46295 | H35: EM00015759 | I35: KI012-D | J35: EM00000000 | K35: KI010-D | N35: EM00015556 | O35: RD11003 | P35: EM00000000 | R35: EM00000000 | T35: EM00000000 | V35: EM00013924 | W35: SSM01-D | X35: EM00000000 | Z35: EM00000000 | AB35: EM00000000 | AD35: EM00000000 | AI35: =IF(D35=1,A35=H35,IF(D35=2,A35=J35,IF(D35=4,A35=N35,IF(D35=6,A35=R35,IF(D35=7,A35=T35,IF(D35=8,A35=V35,IF(D35=9,A35=X35,IF(D35=10,A35=Z35,IF(D35=11,A35=AB35,IF(D35=12,A35=AD35,IF(D35=13,A35=AF35))))))))))) -> TRUE | AJ35: =IF(D35=1,C35=I35,IF(D35=2,C35=K35,IF(D35=4,C35=O35,IF(D35=6,C35=S35,IF(D35=7,C35=U35,IF(D35=8,C35=W35,IF(D35=9,C35=Y35,IF(D35=10,C35=AA35,IF(D35=11,C35=AC35,IF(D35=12,C35=AE35,IF(D35=13,C35=AG35))))))))))) -> TRUE | AK35: =IF(D35=1,J35,IF(D35=2,N35,IF(D35=4,R35,IF(D35=6,T35,IF(D35=7,V35,IF(D35=8,X35,IF(D35=9,Z35))))))) -> EM00000000
A36: =_xlfn.XLOOKUP(C36,[1]Sheet2!$D:$D,[1]Sheet2!$C:$C) -> EM00016027 | B36: 1334 | C36: KI013-D | D36: 1 | E36: 11 | F36: 46266 | G36: 46295 | H36: EM00016027 | I36: KI013-D | J36: EM00000000 | K36: KI010-D | N36: EM00015556 | O36: RD11003 | P36: EM00000000 | R36: EM00000000 | T36: EM00000000 | V36: EM00013924 | W36: SSM01-D | X36: EM00000000 | Z36: EM00000000 | AB36: EM00000000 | AD36: EM00000000 | AI36: =IF(D36=1,A36=H36,IF(D36=2,A36=J36,IF(D36=4,A36=N36,IF(D36=6,A36=R36,IF(D36=7,A36=T36,IF(D36=8,A36=V36,IF(D36=9,A36=X36,IF(D36=10,A36=Z36,IF(D36=11,A36=AB36,IF(D36=12,A36=AD36,IF(D36=13,A36=AF36))))))))))) -> TRUE | AJ36: =IF(D36=1,C36=I36,IF(D36=2,C36=K36,IF(D36=4,C36=O36,IF(D36=6,C36=S36,IF(D36=7,C36=U36,IF(D36=8,C36=W36,IF(D36=9,C36=Y36,IF(D36=10,C36=AA36,IF(D36=11,C36=AC36,IF(D36=12,C36=AE36,IF(D36=13,C36=AG36))))))))))) -> TRUE | AK36: =IF(D36=1,J36,IF(D36=2,N36,IF(D36=4,R36,IF(D36=6,T36,IF(D36=7,V36,IF(D36=8,X36,IF(D36=9,Z36))))))) -> EM00000000
A37: =_xlfn.XLOOKUP(C37,[1]Sheet2!$D:$D,[1]Sheet2!$C:$C) -> EM00015997 | B37: 1334 | C37: KI014-D | D37: 1 | E37: 11 | F37: 46266 | G37: 46295 | H37: EM00015997 | I37: KI014-D | J37: EM00000000 | K37: KI010-D | N37: EM00015556 | O37: RD11003 | P37: EM00000000 | R37: EM00000000 | T37: EM00000000 | V37: EM00013924 | W37: SSM01-D | X37: EM00000000 | Z37: EM00000000 | AB37: EM00000000 | AD37: EM00000000 | AI37: =IF(D37=1,A37=H37,IF(D37=2,A37=J37,IF(D37=4,A37=N37,IF(D37=6,A37=R37,IF(D37=7,A37=T37,IF(D37=8,A37=V37,IF(D37=9,A37=X37,IF(D37=10,A37=Z37,IF(D37=11,A37=AB37,IF(D37=12,A37=AD37,IF(D37=13,A37=AF37))))))))))) -> TRUE | AJ37: =IF(D37=1,C37=I37,IF(D37=2,C37=K37,IF(D37=4,C37=O37,IF(D37=6,C37=S37,IF(D37=7,C37=U37,IF(D37=8,C37=W37,IF(D37=9,C37=Y37,IF(D37=10,C37=AA37,IF(D37=11,C37=AC37,IF(D37=12,C37=AE37,IF(D37=13,C37=AG37))))))))))) -> TRUE | AK37: =IF(D37=1,J37,IF(D37=2,N37,IF(D37=4,R37,IF(D37=6,T37,IF(D37=7,V37,IF(D37=8,X37,IF(D37=9,Z37))))))) -> EM00000000
A38: =_xlfn.XLOOKUP(C38,[1]Sheet2!$D:$D,[1]Sheet2!$C:$C) -> EM00000000 | B38: 1334 | C38: KI015-D | D38: 1 | E38: 11 | F38: 46266 | G38: 46295 | H38: EM00000000 | I38: KI015-D | J38: EM00000000 | K38: KI010-D | N38: EM00015556 | O38: RD11003 | P38: EM00000000 | R38: EM00000000 | T38: EM00000000 | V38: EM00013924 | W38: SSM01-D | X38: EM00000000 | Z38: EM00000000 | AB38: EM00000000 | AD38: EM00000000 | AI38: =IF(D38=1,A38=H38,IF(D38=2,A38=J38,IF(D38=4,A38=N38,IF(D38=6,A38=R38,IF(D38=7,A38=T38,IF(D38=8,A38=V38,IF(D38=9,A38=X38,IF(D38=10,A38=Z38,IF(D38=11,A38=AB38,IF(D38=12,A38=AD38,IF(D38=13,A38=AF38))))))))))) -> TRUE | AJ38: =IF(D38=1,C38=I38,IF(D38=2,C38=K38,IF(D38=4,C38=O38,IF(D38=6,C38=S38,IF(D38=7,C38=U38,IF(D38=8,C38=W38,IF(D38=9,C38=Y38,IF(D38=10,C38=AA38,IF(D38=11,C38=AC38,IF(D38=12,C38=AE38,IF(D38=13,C38=AG38))))))))))) -> TRUE | AK38: =IF(D38=1,J38,IF(D38=2,N38,IF(D38=4,R38,IF(D38=6,T38,IF(D38=7,V38,IF(D38=8,X38,IF(D38=9,Z38))))))) -> EM00000000
A39: =_xlfn.XLOOKUP(C39,[1]Sheet2!$D:$D,[1]Sheet2!$C:$C) -> EM00016516 | B39: 1334 | C39: KI010-D | D39: 2 | E39: 11 | F39: 46266 | G39: 46295 | J39: EM00016516 | K39: KI010-D | N39: EM00015556 | O39: RD11003 | P39: EM00000000 | R39: EM00000000 | T39: EM00000000 | V39: EM00013924 | W39: SSM01-D | X39: EM00000000 | Z39: EM00000000 | AB39: EM00000000 | AD39: EM00000000 | AI39: =IF(D39=1,A39=H39,IF(D39=2,A39=J39,IF(D39=4,A39=N39,IF(D39=6,A39=R39,IF(D39=7,A39=T39,IF(D39=8,A39=V39,IF(D39=9,A39=X39,IF(D39=10,A39=Z39,IF(D39=11,A39=AB39,IF(D39=12,A39=AD39,IF(D39=13,A39=AF39))))))))))) -> TRUE | AJ39: =IF(D39=1,C39=I39,IF(D39=2,C39=K39,IF(D39=4,C39=O39,IF(D39=6,C39=S39,IF(D39=7,C39=U39,IF(D39=8,C39=W39,IF(D39=9,C39=Y39,IF(D39=10,C39=AA39,IF(D39=11,C39=AC39,IF(D39=12,C39=AE39,IF(D39=13,C39=AG39))))))))))) -> TRUE | AK39: =IF(D39=1,J39,IF(D39=2,N39,IF(D39=4,R39,IF(D39=6,T39,IF(D39=7,V39,IF(D39=8,X39,IF(D39=9,Z39))))))) -> EM00015556
A40: =_xlfn.XLOOKUP(C40,[1]Sheet2!$D:$D,[1]Sheet2!$C:$C) -> EM00015588 | B40: 1314 | C40: MY011-D | D40: 1 | E40: 11 | F40: 46266 | G40: 46295 | H40: EM00015588 | I40: MY011-D | J40: EM00015867 | K40: MY010-D | N40: EM00015556 | O40: RD11003 | P40: EM00000000 | R40: EM00000000 | T40: EM00000000 | V40: EM00013924 | W40: SSM01-D | X40: EM00000000 | Z40: EM00000000 | AB40: EM00000000 | AD40: EM00000000 | AI40: =IF(D40=1,A40=H40,IF(D40=2,A40=J40,IF(D40=4,A40=N40,IF(D40=6,A40=R40,IF(D40=7,A40=T40,IF(D40=8,A40=V40,IF(D40=9,A40=X40,IF(D40=10,A40=Z40,IF(D40=11,A40=AB40,IF(D40=12,A40=AD40,IF(D40=13,A40=AF40))))))))))) -> TRUE | AJ40: =IF(D40=1,C40=I40,IF(D40=2,C40=K40,IF(D40=4,C40=O40,IF(D40=6,C40=S40,IF(D40=7,C40=U40,IF(D40=8,C40=W40,IF(D40=9,C40=Y40,IF(D40=10,C40=AA40,IF(D40=11,C40=AC40,IF(D40=12,C40=AE40,IF(D40=13,C40=AG40))))))))))) -> TRUE | AK40: =IF(D40=1,J40,IF(D40=2,N40,IF(D40=4,R40,IF(D40=6,T40,IF(D40=7,V40,IF(D40=8,X40,IF(D40=9,Z40))))))) -> EM00015867
...

Sheet Sheet1
A1: Market wise Sales Target Sep'26
C2: DNR
A3: Market Code | B3: Market Name | C3: Sales Target
A4: CH011-D | B4: CMCH+EPIC-1 | C4: 396020
A5: CH012-D | B5: CMCH+POPULAR+EPIC-2+PEOPLES | C5: 371600 | H5: Region wise Sales Target Sep'26
A6: CH013-D | B6: RAOZAN+RANGAMATI | C6: 717770
A7: CH014-D | B7: CMCH+CSCR+LAB AID | C7: 304270 | J7: DNR
A8: CH015-D | B8: NOAPARA+KAPTAI | C8: 668700 | H8: Region Code | I8: Region Name | J8: Sales Target
A9: CH016-D | B9: HATHAZARI | C9: 464180 | H9: RD11001 | I9: Dhaka-1 | J9: 11241570
A10: CH021-D | B10: FATIKCHARI+KHAGRACHARI | C10: 948650 | H10: RD11002 | I10: Dhaka-2 | J10: 14903650
A11: CH022-D | B11: CMCH+CHEVRON+BELL VIEW | C11: 355330 | H11: RD11003 | I11: Uttara | J11: 13680640
A12: CH023-D | B12: CMCH+PARKVIEW+IBN SINA | C12: 286060 | H12: RD11004 | I12: Sylhet | J12: 23562740
A13: CH024-D | B13: NAZIRHAT | C13: 430920 | H13: RD11005 | I13: Chattogram | J13: 24366840
A14: CH025-D | B14: CIMCH+BOALKHALI | C14: 724550 | H14: RD11006 | I14: Khulna | J14: 15495220
A15: CH031-D | B15: CMOSGH | C15: 389560 | H15: RD11007 | I15: Rajshahi | J15: 9185960
A16: CH032-D | B16: SKIN HOSPITAL | C16: 323140 | H16: RD11008 | I16: Rangpur | J16: 7563380
A17: CH033-D | B17: BANDARTILA | C17: 567360 | I17: Total | J17: =SUM(J9:J16) -> 120000000
A18: CH034-D | B18: JAMALKHAN | C18: 391640
A19: CH035-D | B19: NATIONAL HOSPITAL/MEDICAL CENTER | C19: 346090
A20: CH036-D | B20: O R NIZAM ROAD | C20: 366260
A21: CH037-D | B21: SITAKUNDA+SANDIP | C21: 878110
A22: CH041-D | B22: KERANIHAT+BANDARBAN | C22: 366420
A23: CH042-D | B23: KERANIHAT+DOHAZARI+SATKANIA | C23: 325720
A24: CH043-D | B24: PATIYA | C24: 630140
A25: CH044-D | B25: ANOWARA | C25: 637950
A26: CH045-D | B26: BASHKHALI | C26: 505580
A27: CH711-D | B27: Hazari Lane WH | C27: 15700
A28: CO011-D | B28: COXMCH+ RAMU | C28: 309880
A29: CO012-D | B29: COXMCH+ MOHESKHALI | C29: 484400
... A255: UT025-D | B255: IMCH+TMMCH | C255: 510900
